Workbook

Sheet README
A1: Citi Services — AI Product Strategy Playbook
A2: Working recommendation for the hiring-manager conversation on AI usage and strategy. Built for the AI Product Strategy, Global Services (Director) mandate. Illustrative figures are labeled; verify anything marked [verify] before sending.
A4: What this workbook is
A5: Item | B5: Content | C5: Notes
A6: Purpose | B6: One place that shows how AI strategy is actually done at a top-tier transaction bank that is mid-pack in enterprise AI adoption — and what Services should do across five mandates: Internal, Client, Pricing, Product, Efficiency.
A7: Diagnosis (one line) | B7: Services is #1 in its markets but Citi is #12 in AI (Evident, Oct 2025, down from #8). The binding constraint is not model capability or spend — it is a governed, repeatable path from pilot to P&L, built on shared data/ontology and pulled by client co-creation.
A8: Guiding policy | B8: Ontology before models · one governed pipeline · reuse over rebuild · co-create with 10 clients before scaling to 10,000 · measure P&L, not pilots.
A9: Coherent actions | B9: 8–10 named bets across the five mandates (see Use-Case Portfolio + Roadmap), a delivery pipeline with tiered controls (Operating Model), and a commercial model that monetizes mostly through balances and share of wallet, not feature fees (Pricing & Commercial).
A11: How to read the tabs
A12: Tab | B12: What it covers | C12: Note
A13: 1. Strategy on a Page | B13: The overarching view: diagnosis, five mandates, top bets, horizons, principles. | C13: Start here
A14: 2. Industry & Clients | B14: Deconstruction of the five Services business lines, client segments, and the value chain — with AI opportunity heat. | C14: The territory
A15: 3. Ontology | B15: The entity model (Client → Account → Instruction → Case…), the AI capability taxonomy, and the alignment rule every use case must pass. | C15: Your ontology-aligned view
A16: 4. Maturity Model | B16: 8 dimensions × 5 levels; where Services sits today (assessed), 12/24-month targets, what moves each dimension. | C16: Middle-of-the-pack baseline
A17: 5. Use-Case Portfolio | B17: 40 use cases across the five mandates, scored with editable weights; score and horizon are live formulas. | C17: Edit blue cells
A18: 6. Portfolio Summary | B18: Roll-up: counts and average scores by mandate and horizon; ranked top 12. | C18: Formulas only
A19: 7. Systems View | B19: Stocks & flows, reinforcing/balancing loops, leverage points, binding constraint, archetypes to avoid, delays. | C19: Your systems-oriented view
A20: 8. Operating Model & Governance | B20: How it is done at a global bank: pipeline stages, hub-and-spoke, control tiers, RACI, regulatory map for 30+ markets, model/vendor strategy. | C20: Domain confirmation
A21: 9. Pricing & Commercial | B21: AI for pricing (leakage, relationship pricing, deposit pricing) and pricing of AI (bundled / tiered / usage / value-share / balance-linked).
A22: 10. Business Case | B22: Illustrative value model with editable inputs and low/base/high sensitivities. Replace assumptions with internal baselines. | C22: Edit blue cells
A23: 11. Roadmap | B23: Nine workstreams × five periods (0–90 days to 36 months) with exit criteria.
A24: 12. Benchmarks & Peers | B24: What JPM, BNY, GS, BofA, HSBC, Wells, StanChart, DBS, DB, fintechs and networks have done; adoption benchmarks; copy/adapt/avoid. | C24: Dated, sourced
A25: 13. Panel Review | B25: Product leaders, strategists/business engineers, and systems thinkers: lens, endorsement, push-back, change requested. | C25: Frameworks applied, not quotes
A26: 14. Next Moves (AS) | B26: How to package this for the hiring manager, questions to ask, objections, extensions, verify-before-use list. | C26: For you, not for him
A27: 15. Sources | B27: Source list used across the workbook.
A29: Conventions
A30: Convention | B30: Meaning
A31: Blue text on yellow | B31: Editable input / assumption. Change these; everything downstream recalculates.
A32: Black text | B32: Formula or fixed content.
A33: [verify] | B33: A fact that could not be confirmed from a primary source, or that conflicts across sources. Check before sending.
A34: Scores | B34: 1 (low) to 5 (high). Control burden is inverted in the score (heavier controls lower the score).
A35: Attribution | B35: Strategy frameworks applied include the Business Engineering methodology (Analysis by The Business Engineer, Gennaro Cuofano, businessengineer.ai) alongside Rumelt, Helmer, Meadows, Goldratt, Beer, Cagan, Torres and others named on the Panel Review tab.
A36: Date | B36: Facts current to 22 Sep 2026. Citi financials per Q2 2026 earnings and FY2025 results.

Sheet Strategy on a Page
A1: Strategy on a Page — AI for Citi Services
A2: The whole argument on one tab. Everything else in the workbook is evidence for, or execution of, this page.
A4: Diagnosis → Guiding policy → Coherent action (Rumelt kernel)
A5: Element | B5: Content
A6: Diagnosis | B6: Services is the franchise leader (#1 TTS share 11.5%, FY25 revenue $21.3B, RoTCE 28.6%, >$1T deposits) inside a bank that is mid-pack in AI (Evident #12, down from #8; Leadership pillar 26th, Transparency 30th). Enterprise tooling is broadly deployed (180k+ employees, 40k developers with agents) but Services' value capture is activity-measured (prompts, users, hours), not P&L-measured, and client-facing AI is still in pilot (CitiDirect assistant). The constraint is the governed path from pilot to production — data lineage (consent-order remediation still open), tiered model-risk review for GenAI/agentic (now the bank's own responsibility under SR 26-2), and reusable components — not model capability or budget.
A7: Guiding policy | B7: Treat AI as a product line with a P&L, not a tool rollout. Build one industrialized pipeline (ontology → pattern → controls → production → measurement) and run all five mandates through it. Let client co-creation set demand; let balances and share of wallet — not feature fees — set the commercial model.
A8: Coherent actions | B8: (1) Stand up the Services AI product office with decision rights and a value ledger. (2) Ship the Now-wave bets in the Portfolio (E-01, E-10, I-01, I-03, C-05, P-01, E-03, C-01). (3) Fund the ontology/data foundation as a product with its own roadmap. (4) Convert MRM/controls into a tiered, pre-approved pattern library. (5) Launch a 10-client co-creation cohort per business line. (6) Publish quarterly value realized, internally and (selectively) externally.
A10: Five mandates — what good looks like
A11: Mandate | B11: Objective | C11: North-star metrics | D11: Top bets (IDs → Use-Case Portfolio) | E11: 12-month target | F11: Guardrail
A12: Internal (workforce) | B12: Every Services role has an AI-native workflow; the five Assist pillars run at scale across markets, not in pilots. | C12: Hours redeployed; % roles with AI workflow; adoption ≥ 85% | D12: I-01 Sales Assist/RFP · I-03 Ops Assist investigations · I-02 coverage briefing · I-06 Tech Assist | E12: 3 of 5 Assist pillars at scale in ≥ 20 markets; ≥ 100k hours/yr redeployed in Services (verify vs internal baseline) | F12: Human accountable for every client-facing output; no autonomous client communication
A13: Client (products) | B13: AI features clients stay for and pay for, co-created with named design partners, launched across 30+ markets on one global design. | C13: Client adoption; NPS on AI features; share of wallet; operating deposits | D13: C-05 CitiDirect AI assistant · C-01 cash-flow forecasting · C-04 predictive receivables · C-03 intelligent payment orchestration · C-02 liquidity optimization | E13: 2 client-facing AI products GA in ≥ 10 markets with ≥ 500 active clients; 10-client cohort per business line | F13: Explainability for any recommendation; no client decisioning without validated model + fairness review
A14: Pricing (commercial) | B14: Price to value and stop leakage; deal desk and coverage use one pricing intelligence layer. | C14: Fee realization %; price yield; win rate at target price; deposit beta accuracy | D14: P-01 fee leakage engine · P-02 relationship pricing · P-03 deposit pricing intelligence · P-06 attrition early warning | E14: Leakage recovery live for top-500 relationships; pricing recommendations in ≥ 50% of deal-desk decisions | F14: Conduct and antitrust review of pricing models; documented human override
A15: Product (how we build) | B15: Concept-to-commercialization cycle time halves; localization to 30+ markets is rules-driven from the ontology, not re-coded per market. | C15: Concept→GA cycle time; % specs AI-assisted; markets launched per release | D15: D-03 market localization agent · D-01 discovery synthesis · D-02 AI-assisted specs · D-05 client insight data product | E15: Cycle time −30%; localization backlog for one product cleared via ontology rules | F15: Product decisions remain with accountable PMs; AI drafts, humans decide
A16: Efficiency (ops & risk) | B16: Straight-through processing rises and exceptions fall; document-heavy and alert-heavy work is AI-first with human review by tier. | C16: Cost per transaction; STP rate; exceptions per million; alert dispositions per FTE | D16: E-01 IDP onboarding/KYC · E-10 Agent Assist at scale · E-03 payment repair · E-07 trade doc checking · E-02 screening triage | E16: Servicing effort −20% on 3M+ inquiries; onboarding doc review −80% in all markets; STP +3–5 pts on target flows | F16: Sanctions/AML models stay Tier-4 controlled; no auto-clearing of alerts without validated model
A18: Three horizons
A19: Horizon | B19: Focus | C19: Exit criteria
A20: Now (0–12 months) | B20: Industrialize what already works: IDP, Agent Assist, Ops Assist, Sales Assist, CitiDirect assistant, fee leakage, payment repair. Stand up the pipeline, ontology v1, value ledger, co-creation cohort. | C20: Prove P&L attribution on ≥ 5 use cases; publish first value report
A21: Next (12–24 months) | B21: Client products at scale: forecasting, receivables, orchestration, liquidity optimization advisor; pricing intelligence in deal desk; localization agent; screening triage under Tier-4 controls. | C21: ≥ 2 client products GA in 10+ markets; pricing recs in deal desk; cycle time −30%
A22: Later (24–36 months) | B22: Agentic treasury and agentic payments (Know-Your-Agent rails, Agent Pay for Machines / AP2-class protocols), client insight data products, regulatory reporting and regulatory-change automation, Issuer Services document intelligence. | C22: Services recognized as AI leader in transaction banking (Evident top-5 contribution); AI-attributed revenue disclosed
A24: Operating principles (the rules that resolve trade-offs)
A25: Principle | B25: What it means in practice
A26: 1. Ontology before models | B26: A use case that cannot name its golden-source entities and owners is not ready. Data readiness is scored, not assumed.
A27: 2. One governed pipeline | B27: Every use case — internal or client — flows through the same intake → tiering → validation → controls → monitoring path. Pre-approved patterns make the fast lane fast.
A28: 3. Reuse over rebuild | B28: Components (IDP, retrieval, evals, guardrails, agent runtime) are products with owners; use cases compose them.
A29: 4. Co-create with 10 before scaling to 10,000 | B29: Every client product has named design partners across segments and regions before GA.
A30: 5. Measure P&L, not pilots | B30: Value ledger with Finance sign-off; revenue, cost, risk, client metrics. Prompts and user counts are leading indicators only.
A31: 6. Global design, local controls | B31: Jurisdiction is a first-class entity; rules live in the ontology so 30+ markets are configuration, not code.

Sheet Industry & Clients
A1: Industry & Client Deconstruction — Citi Services
A2: Services = Treasury & Trade Solutions (Payments, Liquidity Management Services, Trade & Working Capital Solutions) + Securities Services (Investor Services, Issuer Services). Facts from Citi Investor Day (May 2026), Q2 2026 earnings, FY2025 results.
A4: A. Business lines — what they do, where the money is, where AI bites
A5: Business line | B5: What it does (platforms) | C5: Scale & position | D5: Economics | E5: Pain points (client / internal) | F5: AI heat (1–5) | G5: Why
A6: Payments | B6: Cross-border and domestic payments, USD clearing for ~300 bank clients in ~40 countries, commercial cards, Payments Express (live in 22 markets, up to 10M payments/day, ~40% of volume), Citi Token Services (5 locations, USD+EUR, ~$1B/day), WorldLink. | C6: #1 globally. FY25 cross-border value $416B (target $482B by 2028); Q2'26 $115B (+13%); USD clearing 177M instructions FY25; card spend $71B FY25; ~$6T processed daily across 180+ countries. | D6: Fees, FX margin, float/NII on transactional balances. Volume-led; unit cost falls with STP. | E6: Client: 'where is my payment', fraud (APP/beneficiary), rail choice (instant vs wire vs tokenized), ISO 20022 data underused. Internal: repairs/returns, sanctions false positives, investigations, 24/7 servicing across time zones. Emerging: agentic commerce (Mastercard Agent Pay, Visa Intelligent Commerce, Google AP2) needs 'Know Your Agent' rails. | F6: 5 | G6: Highest volume, richest structured data (ISO 20022), most exception-driven cost; agentic payments is the next platform shift.
A7: Liquidity Management Services (LMS) | B7: Account structures, pooling and sweeps (2,700+ clients, 80+ countries, ~$24T/yr swept), Real-Time Funding (2024), intercompany and multi-currency liquidity, interest optimization. | C7: #1. Average deposits >$1T (Q2'26 $1.017T, +19%). Target deposit CAGR ~3%. | D7: NII on operating balances dominates Services (FY25 NII $12.2B vs fees $3.1B). Deposit beta and balance mix are the economic engine. | E7: Client: forecasting accuracy, entity/currency structure optimization under local rules, intraday visibility. Internal: deposit classification (operating vs non-operating), pricing sensitivity, regulatory constraints per market. | F7: 4 | G7: Fewer transactions, but each recommendation moves balances — highest NII leverage per use case.
A8: Trade & Working Capital Solutions | B8: Supply-chain finance (~440k buyer–supplier relationships, ~$1T financing throughput in 2025, 'Nirvana' automated supplier onboarding), receivables and payables finance, letters of credit, guarantees, export finance. | C8: #1 in Trade. Document-intensive and credit-adjacent. | D8: Fees + financing margin + working-capital balances. | E8: Client: supplier onboarding speed, document friction (LC, invoices), DSO/DPO optimization. Internal: document checking, sanctions/dual-use screening, supplier risk scoring, compliance review across 160+ countries. | F8: 5 | G8: Unstructured documents everywhere → IDP and agentic checking with human sign-off; HSBC/ANZ/Lloyds/Microsoft PoC shows the pattern.
A9: Investor Services | B9: Custody (100+ markets; proprietary infrastructure in 62), fund services, middle office, Custody+ (Aug 2026: real-time settlement, liquidity sweeping, AI, digital assets; crypto custody targeted 2026). | C9: #4. AUC/AUA $35T (+22%); Securities Services FY25 revenue $5.9B (+15%); settlement volume +37%, cost/txn −25% cited. | D9: Asset-based and activity fees; scale economics in processing. | E9: Client: settlement fails, corporate-action timeliness, reporting. Internal: reconciliations, corporate actions (voluntary events already −92% processing time), client reporting narratives, onboarding. | F9: 4 | G9: Process-heavy back office where agents on reconciliations and corporate actions are proven (Goldman + Anthropic, BNY Eliza).
A10: Issuer Services | B10: Agency & trust, depositary receipts, escrow, structured-finance administration. | C10: #3. Smaller, document- and event-driven. | D10: Fees per deal / per event; long-dated mandates. | E10: Client: investor inquiries, event processing. Internal: indenture/agreement review, payment waterfalls, notices. | F10: 3 | G10: Document intelligence and Q&A; lower volume, lower priority but cheap to add once IDP exists.
A12: B. Client segments — jobs to be done and what they will value from AI
A13: Segment | B13: Jobs to be done | C13: What AI should do for them | D13: Willingness to pay | E13: Adoption readiness | F13: Co-creation candidate?
A14: Large multinational corporates (~80% of Fortune 500) | B14: Run global treasury across dozens of entities and currencies; optimize liquidity; pay and collect at scale; comply everywhere. | C14: Cash-flow forecasting, liquidity structure recommendations, intelligent routing, API/agentic treasury, anomaly alerts, faster onboarding of new entities. | D14: High for optimization that moves working capital; low for 'assistants' (expected free). | E14: High — sophisticated treasury teams, TMS/ERP integrated (Kyriba, SAP, HighRadius already pushing agents). | F14: Yes — 3–4 design partners per region; these are the RFP-driving references.
A15: Financial institutions (~98% of top-100 banks) | B15: USD clearing, correspondent banking, FX, custody; manage sanctions/fraud exposure on flows they don't originate. | C15: Screening quality, fraud/anomaly intelligence (federated with Swift), investigations speed, 24/7 clearing insight. | D15: Medium — pay for risk reduction and speed as part of clearing relationship. | E15: High operationally; cautious on data sharing. | F15: Yes — 2–3 clearing clients for fraud/investigations co-design.
A16: Public sector / sovereigns / IGOs | B16: Disbursements, collections, reserves; strict procurement and residency rules. | C16: Payment orchestration, reconciliation, reporting transparency. | D16: Low–medium; procurement-bound. | E16: Medium; long cycles. | F16: Selective.
A17: Commercial / mid-market (revenue 1.5x since 2022; '$100B addressable') | B17: Simpler treasury, fewer people; want 'done for me'. | C17: CitiDirect Commercial with embedded AI assistant, automated cash application, forecasting out-of-the-box, self-service onboarding. | D17: Medium — bundled tiers work; will pay for outcomes (DSO days). | E17: Medium; fastest-growing segment and most exposed to fintech alternatives (Stripe, Adyen, Tipalti). | F17: Yes — this is where a 'productized' AI tier can be tested first.
A18: Asset managers, asset owners, funds | B18: Custody, fund administration, data and reporting; settlement certainty. | C18: Settlement-fail prediction, corporate-action explainers, reporting narratives, data-as-a-product. | D18: Medium–high for data products. | E18: High. | F18: Yes — via Custody+ design partners.
A20: C. Value chain — where AI applies and how heavy the controls are
A21: Value-chain stage | B21: AI application | C21: Control intensity | D21: Use-case IDs
A22: 1. Sales, RFP, coverage | B22: Retrieve + generate (RFP responses, briefings), propensity models | C22: Low–medium | D22: I-01, I-02, P-04, P-06
A23: 2. Onboarding & KYC / implementation | B23: IDP (extract/classify), workflow agents, policy Q&A | C23: High (KYC/AML) | D23: E-01, I-05, C-08
A24: 3. Account & liquidity structuring | B24: Recommendation/optimization under jurisdictional rules | C24: Medium–high | D24: C-02, P-03
A25: 4. Instruction capture & enrichment | B25: Classification, repair, ISO 20022 enrichment | C25: Medium | D25: E-03, C-03
A26: 5. Screening (sanctions, fraud, AML) | B26: Anomaly detection, alert triage with explanations, federated learning | C26: Highest (Tier 4) | D26: E-02, E-08, C-06
A27: 6. Processing, clearing, settlement | B27: Predict fails, optimize routing, tokenized settlement | C27: High | D27: C-03, C-10
A28: 7. Exceptions, investigations, disputes | B28: Case copilots, agentic outreach drafting, root-cause clustering | C28: Medium | D28: I-03, E-04
A29: 8. Reconciliation & reporting | B29: Break resolution agents, narrative generation, regulatory reporting | C29: Medium–high | D29: E-05, E-06, E-09
A30: 9. Client servicing | B30: Conversational assistants (client and agent-facing), containment | C30: Medium | D30: C-05, E-10, I-04
A31: 10. Pricing & billing | B31: Leakage detection, price optimization, deposit pricing | C31: Medium (conduct) | D31: P-01, P-02, P-03, P-05
A32: 11. Product development & localization | B32: Discovery synthesis, spec drafting, rules-driven localization | C32: Low | D32: D-01…D-05

Sheet Ontology
A1: Ontology — the entity model AI strategy should be aligned to
A2: Object → properties → links → actions. Every use case must name the entities it reads and writes, the golden source, and the control tier. Jurisdiction is a first-class entity so 30+ markets become configuration, not code. Data-readiness scores are assessed, not measured — replace with the Services data catalog.
A4: A. Core entities (object types)
A5: Entity | B5: Key properties | C5: Links to | D5: Golden source (illustrative) | E5: AI patterns that act on it | F5: Use-case IDs | G5: Data readiness (1–5, assessed) | H5: Notes
A6: Client / Legal entity hierarchy | B6: Group → legal entity → operating unit; KYC status; segment; region | C6: Relationship, Account, Document, Case, Fee schedule | D6: KYC/CRM master; onboarding platform | E6: Retrieve, Predict (propensity/attrition), Recommend | F6: I-01, I-02, P-02, P-06, E-01 | G6: 3 | H6: Entity resolution across markets is the classic gap; consent-order data work is the forcing function.
A7: Relationship | B7: Products held, wallet share, coverage team, pricing agreement, revenue by product | C7: Client, Product, Fee schedule, Employee | D7: Revenue/pricing systems; CRM | E7: Predict, Recommend, Optimize | F7: P-02, P-03, P-06, I-02 | G7: 3 | H7: Revenue attribution by product is often reconstructed, not mastered.
A8: Account / Balance | B8: Account type, currency, jurisdiction, operating vs non-operating classification, intraday balance, sweep membership | C8: Client, Jurisdiction, Instruction, Forecast | D8: Core DDA/ledger; liquidity platform | E8: Forecast, Optimize, Detect | F8: C-01, C-02, P-03 | G8: 4 | H8: Balances are well-mastered; classification (operating/non-operating) is the model-relevant attribute to standardize.
A9: Product / Service | B9: Product code, features, market availability, pricing model, controls required | C9: Relationship, Fee schedule, Jurisdiction, Control | D9: Product catalog | E9: Retrieve, Generate (specs/docs) | F9: D-02, D-03, I-01 | G9: 3 | H9: Catalog completeness by market varies; localization agent depends on it.
A10: Instruction (payment / trade / settlement) | B10: ISO 20022 fields, rail, currency pair, urgency, status, repair history | C10: Account, Counterparty, Transaction, Case, Jurisdiction | D10: Payments engines; Payments Express; custody settlement | E10: Classify, Repair, Route, Predict (returns/fails) | F10: E-03, C-03, C-10, C-06 | G10: 4 | H10: ISO 20022 (CBPR+ complete Nov 2025) makes this the richest structured entity — exploit it.
A11: Transaction (posted) | B11: Amount, value date, fees applied, FX rate, linked instruction | C11: Account, Fee schedule, Instruction | D11: Ledgers | E11: Detect (leakage), Reconcile | F11: P-01, P-05, E-05 | G11: 4 | H11: Fee-applied vs fee-contracted comparison is the leakage engine.
A12: Counterparty / Beneficiary | B12: Identity, bank, country, risk rating, history of returns/fraud flags | C12: Instruction, Screening alert, Client | D12: Beneficiary master; screening systems | E12: Detect (anomaly), Classify (risk) | F12: C-06, E-02, E-08 | G12: 3 | H12: Beneficiary change and first-time payee are the highest-signal fraud features.
A13: Document | B13: Type (KYC doc, LC, invoice, contract, indenture), extracted fields, confidence, version, jurisdiction | C13: Client, Instruction, Case, Control | D13: Document platforms; IDP outputs | E13: Extract, Classify, Check (compliance), Generate (summaries) | F13: E-01, E-07, C-07, C-11 | G13: 3 | H13: IDP is proven (~80% cut); the missing piece is a canonical document-type taxonomy across business lines.
A14: Case / Exception | B14: Type (repair, investigation, dispute, break), SLA, root cause, resolution steps, outcome | C14: Instruction, Client, Employee, Inquiry | D14: Case management; gpi tracker | E14: Retrieve, Recommend next step, Generate outreach, Cluster root causes | F14: I-03, E-04, E-05, E-06 | G14: 4 | H14: Case text is the training corpus for Ops Assist; label root causes now.
A15: Inquiry / Interaction | B15: Channel, intent, sentiment, containment, linked case | C15: Client, Case, Employee | D15: Contact-center platform; CitiDirect | E15: Classify intent, Converse, Summarize | F15: C-05, E-10, D-01 | G15: 4 | H15: 3M+ inquiries/yr is the discovery goldmine for product (D-01).
A16: Fee schedule / Price | B16: Contracted fees, tiers, waivers, FX margins, effective dates, approvals | C16: Relationship, Product, Transaction | D16: Billing/pricing systems | E16: Detect (leakage), Optimize, Recommend | F16: P-01, P-02, P-04, P-05 | G16: 2 | H16: Usually the least-digitized entity (contracts in PDFs) — IDP on contracts unlocks P-01.
A17: Jurisdiction / Market | B17: Regulatory rules, formats, cut-offs, data-residency, product availability, local approvals | C17: Product, Instruction, Control, Account | D17: Regulatory inventory; product catalog | E17: Retrieve, Generate (localization rules), Monitor (reg change) | F17: D-03, I-07, C-02 | G17: 2 | H17: Encoding rules as data is the single biggest enabler of 'global design, local adaptation'.
... A21: Forecast / Scenario | B21: Horizon, entity scope, method, accuracy, assumptions | C21: Account, Client, Instruction | D21: Forecasting service (new) | E21: Predict, Simulate | F21: C-01, C-02, P-03 | G21: 2 | H21: New entity — define once and share between client forecasting and deposit pricing.
A23: B. AI capability taxonomy (the verbs)
A24: Capability | B24: What it does | C24: Typical technique | D24: Default control tier | E24: Example use cases | F24: Non-negotiable control
A25: Extract | B25: Turn documents/images into structured fields | C25: IDP (OCR + LLM), layout models | D25: Tier 1–2 (Tier 3 if feeding KYC decisions) | E25: E-01, E-07, C-07 | F25: Confidence thresholds; human review below threshold
A26: Classify / Route | B26: Assign intent, type, queue, risk band | C26: Classifiers, LLM few-shot | D26: Tier 1–3 | E26: E-03, E-10, E-02 | F26: Bias testing where routing affects client outcomes
A27: Predict / Forecast | B27: Estimate future balances, fails, returns, attrition | C27: Gradient boosting, time series, foundation-model features | D27: Tier 2–3 | E27: C-01, C-10, P-06 | F27: Traditional MRM validation applies (in scope of SR 26-2)
A28: Detect / Monitor | B28: Find anomalies, fraud, leakage, drift | C28: Anomaly detection, federated models | D28: Tier 3–4 | E28: C-06, E-08, P-01 | F28: False-positive budget; explanation for every alert
A29: Retrieve / Answer | B29: Ground answers in policies, cases, contracts | C29: RAG over governed corpora | D29: Tier 1–2 | E29: I-04, I-01, I-02 | F29: Entitlement-aware retrieval; citation required
A30: Generate | B30: Draft responses, specs, RFPs, narratives | C30: LLM with templates and evals | D30: Tier 1–2 | E30: I-01, D-02, C-10 | F30: Human edits and sends; no auto-send to clients
A31: Recommend / Decide (with human) | B31: Propose price, structure, next action | C31: Optimization + LLM explanation | D31: Tier 3 | E31: P-02, C-02, C-03 | F31: Documented override; conduct review for pricing
A32: Act (bounded agent) | B32: Execute multi-step tasks within limits | C32: Agent runtime with tools, guardrails, kill switch | D32: Tier 3–4 | E32: E-04, E-05, I-06, C-09 | F32: Action allow-lists, spend/volume caps, post-hoc review, full trace
A33: Simulate / Optimize | B33: Scenario analysis for liquidity, routing, pricing | C33: OR/optimization + ML | D33: Tier 3 | E33: C-02, C-03, P-03 | F33: Assumptions logged; sensitivity shown to user
A35: C. Alignment rule — the test every use case must pass
A36: Use case = (Entities read/written) × (Capability) × (Control tier) × (Accountable owner) × (Golden source confirmed). If any factor is blank, the use case goes to the data/ontology backlog, not the build backlog. This one rule converts 'AI ideas' into a manageable pipeline and is what separates the 5% of enterprises capturing value at scale (BCG, Sep 2025) from the 60% seeing minimal gains.
A37: How it is done elsewhere: banks are converging on object-oriented operational ontologies (Palantir-style object/link/action models are in production at several large FIs), knowledge graphs for KYC/AML entity resolution, and ISO 20022 as the de facto shared payments ontology. Citi's data-lineage remediation under the remaining consent orders is the natural funding vehicle: lineage work and ontology work are the same work, described for two audiences.

Sheet Maturity Model
A1: AI Maturity Model — where Services sits and what moves it
A2: 8 dimensions × 5 levels. 'Today' is an outside-in assessment from public evidence (Investor Day May 2026, Q2'26 call, Evident 2025, press); treat as a hypothesis to validate with the hiring manager. Average ≈ 2.5 = middle of the pack, which matches Evident #12.
A4: Dimension | B4: L1 Exploring | C4: L2 Piloting | D4: L3 Scaling pockets | E4: L4 Industrialized | F4: L5 AI-native | G4: Today (1–5) | H4: Evidence for today | I4: 12-mo target | J4: 24-mo target | K4: What moves the needle
A5: Strategy & value governance | B5: Ad-hoc ideas; no owner | C5: Named pillars and pipeline; activity metrics | D5: Business-line owners; some P&L attribution | E5: Value ledger with Finance sign-off; portfolio managed by ROI | F5: AI P&L disclosed; strategy bets sequenced by value | G5: 3 | H5: Five Assist pillars, 50+ use-case pipeline, EMT sponsorship; but no disclosed $ value (JPM discloses ~$2B); Evident Leadership pillar 26th, Transparency 30th. | I5: 4 | J5: 4 | K5: This role: value ledger, quarterly value report, decision rights. Publish selectively (Transparency pillar).
A6: Data & ontology | B6: Siloed, undocumented | C6: Lineage projects; some catalogs | D6: Shared entities for priority domains | E6: Ontology as product; golden sources enforced | F6: Real-time, entitlement-aware, self-describing data | G6: 2 | H6: Consent-order data/regulatory-reporting remediation still open (Mason, Dec 2025); ISO 20022 richness available; Platforms & Data Solutions exists in Services. | I6: 3 | J6: 4 | K6: Fund ontology v1 for 8 entities (Ontology tab); merge with lineage program; readiness score gates the pipeline.
A7: Platform & tooling | B7: Individual tools | C7: Enterprise assistants deployed | D7: Multi-model access; agent pilots; dev agents | E7: Reusable components (IDP, RAG, evals, agent runtime) with owners | F7: Composable AI platform; cost/inference governed | G7: 3 | H7: Enterprise stack strong (Gemini + Anthropic + Llama; Stylus Workspaces agentic pilot; Copilot/Devin to 40k devs; ~$2B/yr Services platform spend) but Services-specific reusable components not evident. | I7: 4 | J7: 4 | K7: Component roadmap with product owners; cost-per-run telemetry; abstraction layer for model portability.
A8: Model risk & controls | B8: Traditional MRM only | C8: GenAI guidance drafted; case-by-case review | D8: Tiered regime; pre-approved patterns for low tiers | E8: Continuous evals/monitoring; agent controls (allow-lists, kill switch) | F8: Automated evidence; regulator-ready lineage per use case | G8: 3 | H8: Mature MRM culture (SR 11-7 heritage; Services AI risk roles cite SHAP/LIME, AI risk registers). SR 26-2 (Apr 2026) puts GenAI/agentic outside MRM scope → bank's own governance must fill it. | I8: 4 | J8: 4 | K8: Joint MRM–Services pod; tiered control library; eval harness as shared component; publish validation SLAs.
A9: Talent & ways of working | B9: Enthusiasts | C9: Broad training; champions network | D9: Business teams redesign workflows | E9: Roles redefined; AI fluency in performance criteria | F9: AI-native org design; super-ICs | G9: 3 | H9: 180k+ employees on tools, ~70–90% adoption, mandatory prompt training, 4,000 accelerators; but Head of AI left after 7 months (Apr 2026) and AI CoE lead departing (Oct 2026). | I9: 3 | J9: 4 | K9: Workflow redesign (the #1 differentiator of McKinsey 'high performers': 73% vs 25%); stable business-line AI leadership.
A10: Operating model | B10: Central lab | C10: Hub with informal spokes | D10: Business-line AI product leads with budgets | E10: Hub-and-spoke with shared pipeline and decision rights | F10: Federated by default; hub sets standards only | G10: 2 | H10: Firmwide AI org reorganized May 2026 (Group Head of AI; Office of AI Strategy); Services business-line AI roles (this one) being hired now. | I10: 3 | J10: 4 | K10: Define decision rights (Operating Model tab); RACI per use case; one intake.
A11: Client co-creation & commercialization | B11: No client-facing AI | C11: Pilots with a few clients | D11: Named design partners; first GA product | E11: Cohorts per business line; pricing tested; GTM in waves | F11: AI features in every RFP; clients build on Citi's agent rails | G11: 2 | H11: CitiDirect AI assistant in client pilot (+50% containment); Sales Assist internal; no client-facing AI product at BofA CashPro Forecasting scale (3,000+ clients). | I11: 3 | J11: 4 | K11: 10-client cohort per business line; forecasting + receivables GA; pricing experiments in Commercial segment.
A12: Measurement & value realization | B12: Anecdotes | C12: Activity metrics (users, prompts, hours) | D12: Use-case KPIs; some P&L attribution | E12: Value ledger reconciled by Finance; leading and lagging indicators | F12: AI value in external disclosures and targets | G12: 2 | H12: Metrics cited are users/prompts/hours (100k dev hours/wk firmwide); Services cites % effort reductions but no $ figure. | I12: 3 | J12: 4 | K12: Business Case tab as the template; Finance co-owns; report quarterly.
A13: Overall (average) | G13: =ROUND(AVERAGE(G5:G12),2) -> 2.5 | H13: Middle of the pack ≈ 2.5. Target ≈3.4 in 12 months, 4.0 in 24 months. | I13: =ROUND(AVERAGE(I5:I12),2) -> 3.38 | J13: =ROUND(AVERAGE(J5:J12),2) -> 4
A15: Reading the model
A16: Why this matters for the strategy: the two lowest dimensions (Data & ontology; Client co-creation; Measurement; Operating model — all at L2) are exactly the ones a business-line AI product leader can move without new technology. Platform and talent are already L3 thanks to the enterprise program. The plan therefore over-invests in the L2 dimensions during the first 12 months — that is where the score, and the P&L, moves.

Sheet Use-Case Portfolio
A1: Use-Case Portfolio — 40 use cases across five mandates, scored
A2: Score = weighted 1–5 ratings scaled to 100 (control burden inverted). Horizon = Now if score ≥ Now threshold and time-to-value ≤ max; Next if score ≥ Next threshold; else Later. Ratings are outside-in judgments — run this as a workshop with the business line and replace them.
A3: Scoring weights & thresholds (edit blue cells) | B3: Value | C3: 0.3 | D3: Feasibility | E3: 0.2 | F3: Data readiness | G3: 0.15 | H3: Control ease | I3: 0.15 | J3: Strategic fit | K3: 0.2 | L3: =SUM(C3,E3,G3,I3,K3) -> 1 | M3: Now: score ≥ | N3: 77 | O3: Next: score ≥ | P3: 68 | Q3: Now: max TTV (mo) | R3: 9
A5: ID | B5: Mandate | C5: Business line | D5: Value-chain stage | E5: Use case | F5: What it does | G5: AI pattern | H5: Ontology entities | I5: Value type | J5: Value (1–5) | K5: Feasibility (1–5) | L5: Data readiness (1–5) | M5: Control burden (1–5, 5=heaviest) | N5: Time-to-value (months) | O5: Strategic fit (1–5) | P5: Score (0–100) | Q5: Horizon | R5: Peer precedent | S5: Primary KPI | T5: Owner (function) | U5: Rank helper | V5: Rank
A6: I-01 | B6: Internal | C6: All (Sales) | D6: 1. Sales, RFP, coverage | E6: Sales Assist / RFP response engine | F6: Drafts RFP and proposal responses from approved product, pricing and control content; tracks ~10k complex engagements/yr. | G6: Retrieve + Generate | H6: Client, Product, Document, Fee schedule | I6: Revenue (win rate), Cost | J6: 4 | K6: 5 | L6: 4 | M6: 2 | N6: 6 | O6: 5 | P6: =ROUND((J6*$C$3+K6*$E$3+L6*$G$3+(6-M6)*$I$3+O6*$K$3)/$L$3*20,1) -> 88 | Q6: =IF(AND(P6>=$N$3,N6<=$R$3),"Now (0-12m)",IF(P6>=$P$3,"Next (12-24m)","Later (24-36m)")) -> Now (0-12m) | R6: Citi Services already targets this (Investor Day 2026); StanChart SC GPT; GS sales enablement | S6: RFP cycle time; win rate; hours per RFP | T6: Sales enablement + AI product lead | U6: =P6+ROW()/100000 -> 88.00006 | V6: =RANK(U6,$U$6:$U$45,0) -> 4
A7: I-02 | B7: Internal | C7: All (Coverage) | D7: 1. Sales, RFP, coverage | E7: Coverage briefing agent | F7: Pre-meeting brief: balances, flows, open cases, pricing, news; next-best-action suggestions. | G7: Retrieve + Generate + Predict | H7: Client, Relationship, Account, Case | I7: Revenue (share of wallet) | J7: 4 | K7: 4 | L7: 3 | M7: 2 | N7: 6 | O7: 4 | P7: =ROUND((J7*$C$3+K7*$E$3+L7*$G$3+(6-M7)*$I$3+O7*$K$3)/$L$3*20,1) -> 77 | Q7: =IF(AND(P7>=$N$3,N7<=$R$3),"Now (0-12m)",IF(P7>=$P$3,"Next (12-24m)","Later (24-36m)")) -> Now (0-12m) | R7: DBS credit-memo agents (1,500 bankers, ≥30% time saved); Wells Fargo Agentspace | S7: Prep time per meeting; cross-sell actions taken | T7: Coverage + AI product lead | U7: =P7+ROW()/100000 -> 77.00007 | V7: =RANK(U7,$U$6:$U$45,0) -> 22
A8: I-03 | B8: Internal | C8: Payments | D8: 7. Exceptions, investigations | E8: Ops Assist — investigations & inquiry copilot | F8: Resolves 'where is my payment' with gpi tracking, case history, and drafted client responses; suggests next step. | G8: Retrieve + Generate + Recommend | H8: Instruction, Case, Inquiry, Client | I8: Cost, Client experience | J8: 5 | K8: 4 | L8: 4 | M8: 2 | N8: 6 | O8: 5 | P8: =ROUND((J8*$C$3+K8*$E$3+L8*$G$3+(6-M8)*$I$3+O8*$K$3)/$L$3*20,1) -> 90 | Q8: =IF(AND(P8>=$N$3,N8<=$R$3),"Now (0-12m)",IF(P8>=$P$3,"Next (12-24m)","Later (24-36m)")) -> Now (0-12m) | R8: JPM Payments: manual exceptions −50% while volumes +50% | S8: Handle time; cases per FTE; client SLA hit rate | T8: Payments Ops | U8: =P8+ROW()/100000 -> 90.00008 | V8: =RANK(U8,$U$6:$U$45,0) -> 3
A9: I-04 | B9: Internal | C9: All | D9: 9. Client servicing | E9: Policy & procedure Q&A for ops in 90+ markets | F9: Extends Citi Assist with Services procedures, cut-offs and market rules; entitlement-aware. | G9: Retrieve | H9: Control, Jurisdiction, Product, Employee | I9: Cost, Risk | J9: 3 | K9: 5 | L9: 4 | M9: 1 | N9: 3 | O9: 3 | P9: =ROUND((J9*$C$3+K9*$E$3+L9*$G$3+(6-M9)*$I$3+O9*$K$3)/$L$3*20,1) -> 77 | Q9: =IF(AND(P9>=$N$3,N9<=$R$3),"Now (0-12m)",IF(P9>=$P$3,"Next (12-24m)","Later (24-36m)")) -> Now (0-12m) | R9: Citi Assist (enterprise), BofA Erica for Employees (IT calls −50%) | S9: Deflected escalations; time to answer | T9: Ops COO | U9: =P9+ROW()/100000 -> 77.00009 | V9: =RANK(U9,$U$6:$U$45,0) -> 21
A10: I-05 | B10: Internal | C10: All | D10: 2. Onboarding & implementation | E10: Implementation PM copilot | F10: Builds client implementation plans, document checklists and status updates from templates and case history. | G10: Retrieve + Generate | H10: Client, Document, Product, Jurisdiction | I10: Cost, Revenue (time-to-revenue) | J10: 3 | K10: 4 | L10: 3 | M10: 2 | N10: 9 | O10: 4 | P10: =ROUND((J10*$C$3+K10*$E$3+L10*$G$3+(6-M10)*$I$3+O10*$K$3)/$L$3*20,1) -> 71 | Q10: =IF(AND(P10>=$N$3,N10<=$R$3),"Now (0-12m)",IF(P10>=$P$3,"Next (12-24m)","Later (24-36m)")) -> Next (12-24m) | R10: GS client onboarding agents with Anthropic | S10: Implementation cycle time; PM capacity | T10: Implementations | U10: =P10+ROW()/100000 -> 71.0001 | V10: =RANK(U10,$U$6:$U$45,0) -> 32
A11: I-06 | B11: Internal | C11: All (Tech) | D11: 11. Product & localization | E11: Tech Assist — developer agents on Services platforms | F11: Copilot/Devin-class agents for code, tests, upgrades and legacy remediation across Services' estate. | G11: Act (bounded) + Generate | H11: Model/Agent, Product | I11: Cost, Speed | J11: 4 | K11: 5 | L11: 4 | M11: 2 | N11: 3 | O11: 4 | P11: =ROUND((J11*$C$3+K11*$E$3+L11*$G$3+(6-M11)*$I$3+O11*$K$3)/$L$3*20,1) -> 84 | Q11: =IF(AND(P11>=$N$3,N11<=$R$3),"Now (0-12m)",IF(P11>=$P$3,"Next (12-24m)","Later (24-36m)")) -> Now (0-12m) | R11: Citi: 40k devs, Copilot 5–15%, Devin 2–20x on patches; Services cites 30–40% dev productivity | S11: Throughput per dev; change lead time; defect rate | T11: Services Technology | U11: =P11+ROW()/100000 -> 84.00011 | V11: =RANK(U11,$U$6:$U$45,0) -> 9
A12: I-07 | B12: Internal | C12: All | D12: 11. Product & localization | E12: Regulatory-change intelligence agent | F12: Monitors rule changes in 90+ markets, summarizes, maps to products/controls, opens tasks. | G12: Monitor + Retrieve + Generate | H12: Jurisdiction, Control, Product | I12: Risk, Cost | J12: 4 | K12: 3 | L12: 2 | M12: 3 | N12: 12 | O12: 4 | P12: =ROUND((J12*$C$3+K12*$E$3+L12*$G$3+(6-M12)*$I$3+O12*$K$3)/$L$3*20,1) -> 67 | Q12: =IF(AND(P12>=$N$3,N12<=$R$3),"Now (0-12m)",IF(P12>=$P$3,"Next (12-24m)","Later (24-36m)")) -> Later (24-36m) | R12: Common in Compliance (multiple banks); ties to I-07/D-03 localization | S12: Reg changes triaged within SLA; rework avoided | T12: Compliance + Product | U12: =P12+ROW()/100000 -> 67.00012 | V12: =RANK(U12,$U$6:$U$45,0) -> 36
A13: C-01 | B13: Client | C13: LMS | D13: 3. Liquidity structuring | E13: Cash-flow forecasting for treasurers (in CitiDirect) | F13: ML forecasts of balances and flows by entity/currency with accuracy tracking; feeds liquidity decisions. | G13: Predict / Forecast | H13: Account, Instruction, Forecast, Client | I13: Deposits (NII), Retention | J13: 5 | K13: 4 | L13: 4 | M13: 3 | N13: 9 | O13: 5 | P13: =ROUND((J13*$C$3+K13*$E$3+L13*$G$3+(6-M13)*$I$3+O13*$K$3)/$L$3*20,1) -> 87 | Q13: =IF(AND(P13>=$N$3,N13<=$R$3),"Now (0-12m)",IF(P13>=$P$3,"Next (12-24m)","Later (24-36m)")) -> Now (0-12m) | R13: BofA CashPro Forecasting: 3,000+ clients, 250k client hours saved; JPM cites 20–30% accuracy uplift | S13: Active clients; forecast MAPE; operating balances of users | T13: LMS Product | U13: =P13+ROW()/100000 -> 87.00013 | V13: =RANK(U13,$U$6:$U$45,0) -> 7
A14: C-02 | B14: Client | C14: LMS | D14: 3. Liquidity structuring | E14: Liquidity structure optimization advisor | F14: Recommends pooling/sweep/intercompany structures across entities, currencies and jurisdictional constraints. | G14: Recommend + Optimize | H14: Account, Jurisdiction, Forecast, Product | I14: Deposits (NII), Fees | J14: 5 | K14: 3 | L14: 3 | M14: 3 | N14: 12 | O14: 5 | P14: =ROUND((J14*$C$3+K14*$E$3+L14*$G$3+(6-M14)*$I$3+O14*$K$3)/$L$3*20,1) -> 80 | Q14: =IF(AND(P14>=$N$3,N14<=$R$3),"Now (0-12m)",IF(P14>=$P$3,"Next (12-24m)","Later (24-36m)")) -> Next (12-24m) | R14: No scaled peer product yet — white space; Kyriba/HighRadius moving from TMS side | S14: Structures recommended/adopted; balances consolidated | T14: LMS Product | U14: =P14+ROW()/100000 -> 80.00014 | V14: =RANK(U14,$U$6:$U$45,0) -> 16
A15: C-03 | B15: Client | C15: Payments | D15: 4./6. Instruction & processing | E15: Intelligent payment orchestration / routing | F15: Chooses rail (instant, wire, Payments Express, Token Services) by cost, speed, FX, success probability; explains choice. | G15: Recommend + Optimize + Predict | H15: Instruction, Jurisdiction, Counterparty, Fee schedule | I15: Fees, Client experience, Cost | J15: 5 | K15: 3 | L15: 4 | M15: 4 | N15: 12 | O15: 5 | P15: =ROUND((J15*$C$3+K15*$E$3+L15*$G$3+(6-M15)*$I$3+O15*$K$3)/$L$3*20,1) -> 80 | Q15: =IF(AND(P15>=$N$3,N15<=$R$3),"Now (0-12m)",IF(P15>=$P$3,"Next (12-24m)","Later (24-36m)")) -> Next (12-24m) | R15: Named in the JD; Stripe/Adyen do this for merchants; JPM agentic payments | S15: Straight-through rate; cost per payment; client NPS | T15: Payments Product | U15: =P15+ROW()/100000 -> 80.00015 | V15: =RANK(U15,$U$6:$U$45,0) -> 15
A16: C-04 | B16: Client | C16: Trade & WC / Payments | D16: 8. Reconciliation | E16: Predictive receivables & cash application | F16: Matches remittances to invoices, predicts payer behavior and DSO; automates cash application. | G16: Extract + Classify + Predict | H16: Transaction, Document, Counterparty, Client | I16: Fees, Working-capital balances | J16: 4 | K16: 4 | L16: 3 | M16: 3 | N16: 9 | O16: 5 | P16: =ROUND((J16*$C$3+K16*$E$3+L16*$G$3+(6-M16)*$I$3+O16*$K$3)/$L$3*20,1) -> 78 | Q16: =IF(AND(P16>=$N$3,N16<=$R$3),"Now (0-12m)",IF(P16>=$P$3,"Next (12-24m)","Later (24-36m)")) -> Now (0-12m) | R16: Named in the JD; HighRadius (186 agents), SAP Taulia working-capital agent | S16: Auto-match rate; DSO days improved; clients live | T16: Receivables Product | U16: =P16+ROW()/100000 -> 78.00016 | V16: =RANK(U16,$U$6:$U$45,0) -> 17
A17: C-05 | B17: Client | C17: All (CitiDirect) | D17: 9. Client servicing | E17: CitiDirect AI assistant — scale to 30 markets | F17: Conversational servicing and navigation inside CitiDirect; escalates to humans with full context. | G17: Converse + Retrieve | H17: Inquiry, Client, Account, Instruction | I17: Cost, Client experience | J17: 4 | K17: 5 | L17: 4 | M17: 3 | N17: 6 | O17: 5 | P17: =ROUND((J17*$C$3+K17*$E$3+L17*$G$3+(6-M17)*$I$3+O17*$K$3)/$L$3*20,1) -> 85 | Q17: =IF(AND(P17>=$N$3,N17<=$R$3),"Now (0-12m)",IF(P17>=$P$3,"Next (12-24m)","Later (24-36m)")) -> Now (0-12m) | R17: Citi pilot: +50% containment; BofA Erica 3.2B interactions | S17: Containment; CSAT; markets live | T17: Digital Channels | U17: =P17+ROW()/100000 -> 85.00017 | V17: =RANK(U17,$U$6:$U$45,0) -> 8
... A45: E-11 | B45: Efficiency | C45: All (Tech) | D45: 11. Platform simplification | E45: Legacy modernization agents | F45: Agents document, test and migrate legacy Services applications (384 apps retired firmwide in 2025). | G45: Act (bounded) + Generate | H45: Model/Agent, Product | I45: Cost | J45: 4 | K45: 4 | L45: 4 | M45: 2 | N45: 12 | O45: 3 | P45: =ROUND((J45*$C$3+K45*$E$3+L45*$G$3+(6-M45)*$I$3+O45*$K$3)/$L$3*20,1) -> 76 | Q45: =IF(AND(P45>=$N$3,N45<=$R$3),"Now (0-12m)",IF(P45>=$P$3,"Next (12-24m)","Later (24-36m)")) -> Next (12-24m) | R45: Citi Devin usage on upgrades/rewrites | S45: Apps retired; run-cost saved | T45: Services Technology | U45: =P45+ROW()/100000 -> 76.00045 | V45: =RANK(U45,$U$6:$U$45,0) -> 23
A47: Mandate codes: I = Internal (workforce), C = Client (products), P = Pricing (commercial), D = Product (how we build), E = Efficiency (operations & risk). Control burden 5 = Tier-4 (client decisioning / sanctions-AML); 1 = Tier-1 assist. Peer precedents dated 2025–2026; see Benchmarks & Peers for sources.

Sheet Portfolio Summary
A1: Portfolio Summary — roll-up of the scored portfolio (all formulas)
A2: Recalculates from the Use-Case Portfolio. Use it to check mix: the base of the pyramid (productivity/efficiency) should dominate Now; strategic client bets should dominate Next; agentic/platform bets sit in Later.
A4: A. By mandate
A5: Mandate | B5: # use cases | C5: Avg score | D5: # Now (0-12m) | E5: # Next (12-24m) | F5: # Later (24-36m)
A6: Internal | B6: =COUNTIF('Use-Case Portfolio'!$B$6:$B$45,A6) -> 7 | C6: =IFERROR(ROUND(AVERAGEIF('Use-Case Portfolio'!$B$6:$B$45,A6,'Use-Case Portfolio'!$P$6:$P$45),1),0) -> 79.1 | D6: =COUNTIFS('Use-Case Portfolio'!$B$6:$B$45,A6,'Use-Case Portfolio'!$Q$6:$Q$45,"Now*") -> 5 | E6: =COUNTIFS('Use-Case Portfolio'!$B$6:$B$45,A6,'Use-Case Portfolio'!$Q$6:$Q$45,"Next*") -> 1 | F6: =COUNTIFS('Use-Case Portfolio'!$B$6:$B$45,A6,'Use-Case Portfolio'!$Q$6:$Q$45,"Later*") -> 1
A7: Client | B7: =COUNTIF('Use-Case Portfolio'!$B$6:$B$45,A7) -> 11 | C7: =IFERROR(ROUND(AVERAGEIF('Use-Case Portfolio'!$B$6:$B$45,A7,'Use-Case Portfolio'!$P$6:$P$45),1),0) -> 75.2 | D7: =COUNTIFS('Use-Case Portfolio'!$B$6:$B$45,A7,'Use-Case Portfolio'!$Q$6:$Q$45,"Now*") -> 3 | E7: =COUNTIFS('Use-Case Portfolio'!$B$6:$B$45,A7,'Use-Case Portfolio'!$Q$6:$Q$45,"Next*") -> 6 | F7: =COUNTIFS('Use-Case Portfolio'!$B$6:$B$45,A7,'Use-Case Portfolio'!$Q$6:$Q$45,"Later*") -> 2
A8: Pricing | B8: =COUNTIF('Use-Case Portfolio'!$B$6:$B$45,A8) -> 6 | C8: =IFERROR(ROUND(AVERAGEIF('Use-Case Portfolio'!$B$6:$B$45,A8,'Use-Case Portfolio'!$P$6:$P$45),1),0) -> 78 | D8: =COUNTIFS('Use-Case Portfolio'!$B$6:$B$45,A8,'Use-Case Portfolio'!$Q$6:$Q$45,"Now*") -> 2 | E8: =COUNTIFS('Use-Case Portfolio'!$B$6:$B$45,A8,'Use-Case Portfolio'!$Q$6:$Q$45,"Next*") -> 4 | F8: =COUNTIFS('Use-Case Portfolio'!$B$6:$B$45,A8,'Use-Case Portfolio'!$Q$6:$Q$45,"Later*") -> 0
A9: Product | B9: =COUNTIF('Use-Case Portfolio'!$B$6:$B$45,A9) -> 5 | C9: =IFERROR(ROUND(AVERAGEIF('Use-Case Portfolio'!$B$6:$B$45,A9,'Use-Case Portfolio'!$P$6:$P$45),1),0) -> 71.2 | D9: =COUNTIFS('Use-Case Portfolio'!$B$6:$B$45,A9,'Use-Case Portfolio'!$Q$6:$Q$45,"Now*") -> 2 | E9: =COUNTIFS('Use-Case Portfolio'!$B$6:$B$45,A9,'Use-Case Portfolio'!$Q$6:$Q$45,"Next*") -> 1 | F9: =COUNTIFS('Use-Case Portfolio'!$B$6:$B$45,A9,'Use-Case Portfolio'!$Q$6:$Q$45,"Later*") -> 2
A10: Efficiency | B10: =COUNTIF('Use-Case Portfolio'!$B$6:$B$45,A10) -> 11 | C10: =IFERROR(ROUND(AVERAGEIF('Use-Case Portfolio'!$B$6:$B$45,A10,'Use-Case Portfolio'!$P$6:$P$45),1),0) -> 78.5 | D10: =COUNTIFS('Use-Case Portfolio'!$B$6:$B$45,A10,'Use-Case Portfolio'!$Q$6:$Q$45,"Now*") -> 6 | E10: =COUNTIFS('Use-Case Portfolio'!$B$6:$B$45,A10,'Use-Case Portfolio'!$Q$6:$Q$45,"Next*") -> 4 | F10: =COUNTIFS('Use-Case Portfolio'!$B$6:$B$45,A10,'Use-Case Portfolio'!$Q$6:$Q$45,"Later*") -> 1
A11: Total | B11: =SUM(B6:B10) -> 40 | C11: =ROUND(AVERAGE('Use-Case Portfolio'!$P$6:$P$45),1) -> 76.7 | D11: =SUM(D6:D10) -> 18 | E11: =SUM(E6:E10) -> 16 | F11: =SUM(F6:F10) -> 6
A13: B. Mix check vs recommended allocation (share of use cases)
A14: Horizon | B14: Actual # | C14: Actual % | D14: Recommended % | E14: Gap (pts) | F14: Read
A15: Now (0-12m) | B15: =D11 -> 18 | C15: =IFERROR(B15/$B$11,0) -> 0.45 | D15: 0.45 | E15: =(C15-D15)*100 -> 0 | F15: Productivity and efficiency base — proven patterns, fast value
A16: Next (12-24m) | B16: =E11 -> 16 | C16: =IFERROR(B16/$B$11,0) -> 0.4 | D16: 0.4 | E16: =(C16-D16)*100 -> 0 | F16: Client products and pricing intelligence — the differentiation layer
A17: Later (24-36m) | B17: =F11 -> 6 | C17: =IFERROR(B17/$B$11,0) -> 0.15 | D17: 0.15 | E17: =(C17-D17)*100 -> 0 | F17: Agentic rails, data products, structural bets — convex, small position
A18: Recommended split adapts the AI Implementation Pyramid (≈70/15/10/5 of budget across productivity / workflow automation / strategic advantage / R&D bets) to a use-case count. Budget share will skew more to Now than count share does, because Now items are cheaper per unit.
A20: C. Top 12 by score (ranked; ties broken by row order)
A21: Rank | B21: ID | C21: Use case | D21: Mandate | E21: Score | F21: Horizon
A22: 1 | B22: =INDEX('Use-Case Portfolio'!$A$6:$A$45,MATCH(A22,'Use-Case Portfolio'!$V$6:$V$45,0)) -> E-10 | C22: =INDEX('Use-Case Portfolio'!$E$6:$E$45,MATCH(A22,'Use-Case Portfolio'!$V$6:$V$45,0)) -> CitiService Agent Assist — 6,000 agents / 72 countries | D22: =INDEX('Use-Case Portfolio'!$B$6:$B$45,MATCH(A22,'Use-Case Portfolio'!$V$6:$V$45,0)) -> Efficiency | E22: =INDEX('Use-Case Portfolio'!$P$6:$P$45,MATCH(A22,'Use-Case Portfolio'!$V$6:$V$45,0)) -> 94 | F22: =INDEX('Use-Case Portfolio'!$Q$6:$Q$45,MATCH(A22,'Use-Case Portfolio'!$V$6:$V$45,0)) -> Now (0-12m)
A23: 2 | B23: =INDEX('Use-Case Portfolio'!$A$6:$A$45,MATCH(A23,'Use-Case Portfolio'!$V$6:$V$45,0)) -> E-01 | C23: =INDEX('Use-Case Portfolio'!$E$6:$E$45,MATCH(A23,'Use-Case Portfolio'!$V$6:$V$45,0)) -> IDP for onboarding/KYC documents — all markets | D23: =INDEX('Use-Case Portfolio'!$B$6:$B$45,MATCH(A23,'Use-Case Portfolio'!$V$6:$V$45,0)) -> Efficiency | E23: =INDEX('Use-Case Portfolio'!$P$6:$P$45,MATCH(A23,'Use-Case Portfolio'!$V$6:$V$45,0)) -> 91 | F23: =INDEX('Use-Case Portfolio'!$Q$6:$Q$45,MATCH(A23,'Use-Case Portfolio'!$V$6:$V$45,0)) -> Now (0-12m)
A24: 3 | B24: =INDEX('Use-Case Portfolio'!$A$6:$A$45,MATCH(A24,'Use-Case Portfolio'!$V$6:$V$45,0)) -> I-03 | C24: =INDEX('Use-Case Portfolio'!$E$6:$E$45,MATCH(A24,'Use-Case Portfolio'!$V$6:$V$45,0)) -> Ops Assist — investigations & inquiry copilot | D24: =INDEX('Use-Case Portfolio'!$B$6:$B$45,MATCH(A24,'Use-Case Portfolio'!$V$6:$V$45,0)) -> Internal | E24: =INDEX('Use-Case Portfolio'!$P$6:$P$45,MATCH(A24,'Use-Case Portfolio'!$V$6:$V$45,0)) -> 90 | F24: =INDEX('Use-Case Portfolio'!$Q$6:$Q$45,MATCH(A24,'Use-Case Portfolio'!$V$6:$V$45,0)) -> Now (0-12m)
A25: 4 | B25: =INDEX('Use-Case Portfolio'!$A$6:$A$45,MATCH(A25,'Use-Case Portfolio'!$V$6:$V$45,0)) -> I-01 | C25: =INDEX('Use-Case Portfolio'!$E$6:$E$45,MATCH(A25,'Use-Case Portfolio'!$V$6:$V$45,0)) -> Sales Assist / RFP response engine | D25: =INDEX('Use-Case Portfolio'!$B$6:$B$45,MATCH(A25,'Use-Case Portfolio'!$V$6:$V$45,0)) -> Internal | E25: =INDEX('Use-Case Portfolio'!$P$6:$P$45,MATCH(A25,'Use-Case Portfolio'!$V$6:$V$45,0)) -> 88 | F25: =INDEX('Use-Case Portfolio'!$Q$6:$Q$45,MATCH(A25,'Use-Case Portfolio'!$V$6:$V$45,0)) -> Now (0-12m)
A26: 5 | B26: =INDEX('Use-Case Portfolio'!$A$6:$A$45,MATCH(A26,'Use-Case Portfolio'!$V$6:$V$45,0)) -> E-03 | C26: =INDEX('Use-Case Portfolio'!$E$6:$E$45,MATCH(A26,'Use-Case Portfolio'!$V$6:$V$45,0)) -> Payment repair & STP uplift | D26: =INDEX('Use-Case Portfolio'!$B$6:$B$45,MATCH(A26,'Use-Case Portfolio'!$V$6:$V$45,0)) -> Efficiency | E26: =INDEX('Use-Case Portfolio'!$P$6:$P$45,MATCH(A26,'Use-Case Portfolio'!$V$6:$V$45,0)) -> 87 | F26: =INDEX('Use-Case Portfolio'!$Q$6:$Q$45,MATCH(A26,'Use-Case Portfolio'!$V$6:$V$45,0)) -> Now (0-12m)
A27: 6 | B27: =INDEX('Use-Case Portfolio'!$A$6:$A$45,MATCH(A27,'Use-Case Portfolio'!$V$6:$V$45,0)) -> P-01 | C27: =INDEX('Use-Case Portfolio'!$E$6:$E$45,MATCH(A27,'Use-Case Portfolio'!$V$6:$V$45,0)) -> Fee leakage & billing accuracy engine | D27: =INDEX('Use-Case Portfolio'!$B$6:$B$45,MATCH(A27,'Use-Case Portfolio'!$V$6:$V$45,0)) -> Pricing | E27: =INDEX('Use-Case Portfolio'!$P$6:$P$45,MATCH(A27,'Use-Case Portfolio'!$V$6:$V$45,0)) -> 87 | F27: =INDEX('Use-Case Portfolio'!$Q$6:$Q$45,MATCH(A27,'Use-Case Portfolio'!$V$6:$V$45,0)) -> Now (0-12m)
A28: 7 | B28: =INDEX('Use-Case Portfolio'!$A$6:$A$45,MATCH(A28,'Use-Case Portfolio'!$V$6:$V$45,0)) -> C-01 | C28: =INDEX('Use-Case Portfolio'!$E$6:$E$45,MATCH(A28,'Use-Case Portfolio'!$V$6:$V$45,0)) -> Cash-flow forecasting for treasurers (in CitiDirect) | D28: =INDEX('Use-Case Portfolio'!$B$6:$B$45,MATCH(A28,'Use-Case Portfolio'!$V$6:$V$45,0)) -> Client | E28: =INDEX('Use-Case Portfolio'!$P$6:$P$45,MATCH(A28,'Use-Case Portfolio'!$V$6:$V$45,0)) -> 87 | F28: =INDEX('Use-Case Portfolio'!$Q$6:$Q$45,MATCH(A28,'Use-Case Portfolio'!$V$6:$V$45,0)) -> Now (0-12m)
A29: 8 | B29: =INDEX('Use-Case Portfolio'!$A$6:$A$45,MATCH(A29,'Use-Case Portfolio'!$V$6:$V$45,0)) -> C-05 | C29: =INDEX('Use-Case Portfolio'!$E$6:$E$45,MATCH(A29,'Use-Case Portfolio'!$V$6:$V$45,0)) -> CitiDirect AI assistant — scale to 30 markets | D29: =INDEX('Use-Case Portfolio'!$B$6:$B$45,MATCH(A29,'Use-Case Portfolio'!$V$6:$V$45,0)) -> Client | E29: =INDEX('Use-Case Portfolio'!$P$6:$P$45,MATCH(A29,'Use-Case Portfolio'!$V$6:$V$45,0)) -> 85 | F29: =INDEX('Use-Case Portfolio'!$Q$6:$Q$45,MATCH(A29,'Use-Case Portfolio'!$V$6:$V$45,0)) -> Now (0-12m)
A30: 9 | B30: =INDEX('Use-Case Portfolio'!$A$6:$A$45,MATCH(A30,'Use-Case Portfolio'!$V$6:$V$45,0)) -> I-06 | C30: =INDEX('Use-Case Portfolio'!$E$6:$E$45,MATCH(A30,'Use-Case Portfolio'!$V$6:$V$45,0)) -> Tech Assist — developer agents on Services platforms | D30: =INDEX('Use-Case Portfolio'!$B$6:$B$45,MATCH(A30,'Use-Case Portfolio'!$V$6:$V$45,0)) -> Internal | E30: =INDEX('Use-Case Portfolio'!$P$6:$P$45,MATCH(A30,'Use-Case Portfolio'!$V$6:$V$45,0)) -> 84 | F30: =INDEX('Use-Case Portfolio'!$Q$6:$Q$45,MATCH(A30,'Use-Case Portfolio'!$V$6:$V$45,0)) -> Now (0-12m)
A31: 10 | B31: =INDEX('Use-Case Portfolio'!$A$6:$A$45,MATCH(A31,'Use-Case Portfolio'!$V$6:$V$45,0)) -> E-07 | C31: =INDEX('Use-Case Portfolio'!$E$6:$E$45,MATCH(A31,'Use-Case Portfolio'!$V$6:$V$45,0)) -> Trade finance document checking | D31: =INDEX('Use-Case Portfolio'!$B$6:$B$45,MATCH(A31,'Use-Case Portfolio'!$V$6:$V$45,0)) -> Efficiency | E31: =INDEX('Use-Case Portfolio'!$P$6:$P$45,MATCH(A31,'Use-Case Portfolio'!$V$6:$V$45,0)) -> 81 | F31: =INDEX('Use-Case Portfolio'!$Q$6:$Q$45,MATCH(A31,'Use-Case Portfolio'!$V$6:$V$45,0)) -> Now (0-12m)
A32: 11 | B32: =INDEX('Use-Case Portfolio'!$A$6:$A$45,MATCH(A32,'Use-Case Portfolio'!$V$6:$V$45,0)) -> D-01 | C32: =INDEX('Use-Case Portfolio'!$E$6:$E$45,MATCH(A32,'Use-Case Portfolio'!$V$6:$V$45,0)) -> Discovery synthesis from inquiries & interviews | D32: =INDEX('Use-Case Portfolio'!$B$6:$B$45,MATCH(A32,'Use-Case Portfolio'!$V$6:$V$45,0)) -> Product | E32: =INDEX('Use-Case Portfolio'!$P$6:$P$45,MATCH(A32,'Use-Case Portfolio'!$V$6:$V$45,0)) -> 81 | F32: =INDEX('Use-Case Portfolio'!$Q$6:$Q$45,MATCH(A32,'Use-Case Portfolio'!$V$6:$V$45,0)) -> Now (0-12m)
A33: 12 | B33: =INDEX('Use-Case Portfolio'!$A$6:$A$45,MATCH(A33,'Use-Case Portfolio'!$V$6:$V$45,0)) -> P-06 | C33: =INDEX('Use-Case Portfolio'!$E$6:$E$45,MATCH(A33,'Use-Case Portfolio'!$V$6:$V$45,0)) -> Attrition & wallet-share early warning | D33: =INDEX('Use-Case Portfolio'!$B$6:$B$45,MATCH(A33,'Use-Case Portfolio'!$V$6:$V$45,0)) -> Pricing | E33: =INDEX('Use-Case Portfolio'!$P$6:$P$45,MATCH(A33,'Use-Case Portfolio'!$V$6:$V$45,0)) -> 80 | F33: =INDEX('Use-Case Portfolio'!$Q$6:$Q$45,MATCH(A33,'Use-Case Portfolio'!$V$6:$V$45,0)) -> Now (0-12m)

Sheet Systems View
A1: Systems View — the AI program as a system, not a list of projects
A2: Purpose of the system (Ackoff): convert Services' data exhaust and client relationships into governed, compounding decision capability that lowers cost-to-serve and raises client value within the bank's risk appetite. Read: stocks → loops → leverage points → binding constraint → archetypes to avoid → delays.
A4: A. Stocks and flows (what accumulates)
A5: Stock | B5: Inflows | C5: Outflows / leaks | D5: State today (assessed) | E5: Target signal
A6: Trusted, ontology-mapped data | B6: Lineage work, golden-source designation, ISO 20022 adoption | C6: Schema drift, market-specific exceptions, unowned datasets | D6: Low-medium: consent-order remediation still open; ontology not yet a product | E6: Readiness score ≥ 4 on the 8 priority entities
A7: Reusable AI components | B7: Component product owners, platform funding, pattern extraction from use cases | C7: Bespoke builds, vendor lock-in, unmaintained pilots | D7: Enterprise stack strong; Services-specific components thin | E7: ≥ 6 components with owners and SLAs (IDP, RAG, evals, guardrails, agent runtime, telemetry)
A8: Validated models/agents in inventory | B8: Pipeline throughput (validation capacity × pre-approved patterns) | C8: Retirement, drift failures, regulatory re-scoping | D8: 50+ use-case pipeline; production count undisclosed | E8: ≥ 25 in production with monitoring
A9: Control coverage | B9: Tiered control library, eval harness, monitoring | C9: New capability classes (agents) outpacing controls | D9: Traditional MRM mature; GenAI/agentic controls forming (SR 26-2 shifts onus to bank) | E9: 100% of Tier-3/4 use cases with evidence pack
A10: Client trust and co-creation relationships | B10: Design-partner cohorts, transparent explanations, reliability | C10: Incidents, opaque recommendations, over-automation | D10: CitiDirect assistant pilot; Sales Assist; few named client co-creation programs | E10: 10 design partners per business line; NPS on AI features tracked
A11: Workforce AI fluency | B11: Training (mandatory prompt training), accelerators, workflow redesign | C11: Attrition of AI leaders, tool fatigue | D11: 70–90% adoption; AI leadership churn in 2026 | E11: Roles redesigned; fluency in performance criteria
A12: Value realized (P&L) | B12: Use cases reaching scale with Finance-verified attribution | C12: Benefit leakage (hours saved not redeployed), double counting | D12: Activity metrics dominate; no $ disclosed | E12: Value ledger reconciled quarterly; AI-attributed revenue and cost published
A14: B. Feedback loops (R = reinforcing, B = balancing)
